Traceback (most recent call last):
  File "/home/rresq/github/os-labs/gerando_excessao/error_log.py", line 4, in <module>
    raise Exception('This is the error message')
Exception: This is the error message
